Workbook

Sheet Demand Projection
A1: No | B1: Produk | C1: Tanggal Order | D1: Jumlah
A2: 1 | B2: SKU PROD A | C2: 46025 | D2: 1000
A3: 2 | B3: SKU PROD B | C3: 46025 | D3: 6000
A4: 3 | B4: SKU PROD A | C4: 46026 | D4: 400
A5: 4 | B5: SKU PROD C | C5: 46027 | D5: 900
A6: 5 | B6: SKU PROD D | C6: 46028 | D6: 600
A7: 6 | B7: SKU PROD A | C7: 46029 | D7: 1000
A8: 7 | B8: SKU PROD C | C8: 46031 | D8: 500
A9: 8 | B9: SKU PROD E | C9: 46034 | D9: 400
A10: 9 | B10: SKU PROD B | C10: 46035 | D10: 600
A11: 10 | B11: SKU PROD D | C11: 46039 | D11: 900
A12: 11 | B12: SKU PROD C | C12: 46042 | D12: 800
A13: 12 | B13: SKU PROD A | C13: 46046 | D13: 1000
... A15: 14 | B15: SKU PROD E | C15: 46050 | D15: 2000
A16: 15 | B16: =B2 -> SKU PROD A | C16: =EDATE(C2,1) -> 46056 | D16: {=_xlfn.LET( _xlpm.m,MONTH(C16), _xlpm.d,DAY(C16), _xlpm.r, _xlfn.SWITCH( _xlpm.m, 2,IF(_xlpm.d<15,5%,7.5%), 3,IF(_xlpm.d<20,-2%,1.5%), 4,IF(_xlpm.d<17,2.5%,-5%), 5,IF(_xlpm.d<22,-5%,5%), 6,-5%, 7,IF(_xlpm.d<10,15%,-5%), 8,IF(_xlpm.d<25,-15%,3%), 9,IF(_xlpm.d<25,-15%,3%), 10,IF(_xlpm.d<11,-10%,-5%), 11,IF(_xlpm.d<13,12%,6%), 12,IF(_xlpm.d<10,6%,12%) ), ROUNDUP(D2*(1+_xlpm.r),0) )} -> 1050
A17: 16 | B17: =B3 -> SKU PROD B | C17: =EDATE(C3,1) -> 46056 | D17: {=_xlfn.LET( _xlpm.m,MONTH(C17), _xlpm.d,DAY(C17), _xlpm.r, _xlfn.SWITCH( _xlpm.m, 2,IF(_xlpm.d<15,5%,7.5%), 3,IF(_xlpm.d<20,-2%,1.5%), 4,IF(_xlpm.d<17,2.5%,-5%), 5,IF(_xlpm.d<22,-5%,5%), 6,-5%, 7,IF(_xlpm.d<10,15%,-5%), 8,IF(_xlpm.d<25,-15%,3%), 9,IF(_xlpm.d<25,-15%,3%), 10,IF(_xlpm.d<11,-10%,-5%), 11,IF(_xlpm.d<13,12%,6%), 12,IF(_xlpm.d<10,6%,12%) ), ROUNDUP(D3*(1+_xlpm.r),0) )} -> 6300
A18: 17 | B18: =B4 -> SKU PROD A | C18: =EDATE(C4,1) -> 46057 | D18: {=_xlfn.LET( _xlpm.m,MONTH(C18), _xlpm.d,DAY(C18), _xlpm.r, _xlfn.SWITCH( _xlpm.m, 2,IF(_xlpm.d<15,5%,7.5%), 3,IF(_xlpm.d<20,-2%,1.5%), 4,IF(_xlpm.d<17,2.5%,-5%), 5,IF(_xlpm.d<22,-5%,5%), 6,-5%, 7,IF(_xlpm.d<10,15%,-5%), 8,IF(_xlpm.d<25,-15%,3%), 9,IF(_xlpm.d<25,-15%,3%), 10,IF(_xlpm.d<11,-10%,-5%), 11,IF(_xlpm.d<13,12%,6%), 12,IF(_xlpm.d<10,6%,12%) ), ROUNDUP(D4*(1+_xlpm.r),0) )} -> 420
A19: 18 | B19: =B5 -> SKU PROD C | C19: =EDATE(C5,1) -> 46058 | D19: {=_xlfn.LET( _xlpm.m,MONTH(C19), _xlpm.d,DAY(C19), _xlpm.r, _xlfn.SWITCH( _xlpm.m, 2,IF(_xlpm.d<15,5%,7.5%), 3,IF(_xlpm.d<20,-2%,1.5%), 4,IF(_xlpm.d<17,2.5%,-5%), 5,IF(_xlpm.d<22,-5%,5%), 6,-5%, 7,IF(_xlpm.d<10,15%,-5%), 8,IF(_xlpm.d<25,-15%,3%), 9,IF(_xlpm.d<25,-15%,3%), 10,IF(_xlpm.d<11,-10%,-5%), 11,IF(_xlpm.d<13,12%,6%), 12,IF(_xlpm.d<10,6%,12%) ), ROUNDUP(D5*(1+_xlpm.r),0) )} -> 945
A20: 19 | B20: =B6 -> SKU PROD D | C20: =EDATE(C6,1) -> 46059 | D20: {=_xlfn.LET( _xlpm.m,MONTH(C20), _xlpm.d,DAY(C20), _xlpm.r, _xlfn.SWITCH( _xlpm.m, 2,IF(_xlpm.d<15,5%,7.5%), 3,IF(_xlpm.d<20,-2%,1.5%), 4,IF(_xlpm.d<17,2.5%,-5%), 5,IF(_xlpm.d<22,-5%,5%), 6,-5%, 7,IF(_xlpm.d<10,15%,-5%), 8,IF(_xlpm.d<25,-15%,3%), 9,IF(_xlpm.d<25,-15%,3%), 10,IF(_xlpm.d<11,-10%,-5%), 11,IF(_xlpm.d<13,12%,6%), 12,IF(_xlpm.d<10,6%,12%) ), ROUNDUP(D6*(1+_xlpm.r),0) )} -> 630
A21: 20 | B21: =B7 -> SKU PROD A | C21: =EDATE(C7,1) -> 46060 | D21: {=_xlfn.LET( _xlpm.m,MONTH(C21), _xlpm.d,DAY(C21), _xlpm.r, _xlfn.SWITCH( _xlpm.m, 2,IF(_xlpm.d<15,5%,7.5%), 3,IF(_xlpm.d<20,-2%,1.5%), 4,IF(_xlpm.d<17,2.5%,-5%), 5,IF(_xlpm.d<22,-5%,5%), 6,-5%, 7,IF(_xlpm.d<10,15%,-5%), 8,IF(_xlpm.d<25,-15%,3%), 9,IF(_xlpm.d<25,-15%,3%), 10,IF(_xlpm.d<11,-10%,-5%), 11,IF(_xlpm.d<13,12%,6%), 12,IF(_xlpm.d<10,6%,12%) ), ROUNDUP(D7*(1+_xlpm.r),0) )} -> 1050
A22: 21 | B22: =B8 -> SKU PROD C | C22: =EDATE(C8,1) -> 46062 | D22: {=_xlfn.LET( _xlpm.m,MONTH(C22), _xlpm.d,DAY(C22), _xlpm.r, _xlfn.SWITCH( _xlpm.m, 2,IF(_xlpm.d<15,5%,7.5%), 3,IF(_xlpm.d<20,-2%,1.5%), 4,IF(_xlpm.d<17,2.5%,-5%), 5,IF(_xlpm.d<22,-5%,5%), 6,-5%, 7,IF(_xlpm.d<10,15%,-5%), 8,IF(_xlpm.d<25,-15%,3%), 9,IF(_xlpm.d<25,-15%,3%), 10,IF(_xlpm.d<11,-10%,-5%), 11,IF(_xlpm.d<13,12%,6%), 12,IF(_xlpm.d<10,6%,12%) ), ROUNDUP(D8*(1+_xlpm.r),0) )} -> 525
A23: 22 | B23: =B9 -> SKU PROD E | C23: =EDATE(C9,1) -> 46065 | D23: {=_xlfn.LET( _xlpm.m,MONTH(C23), _xlpm.d,DAY(C23), _xlpm.r, _xlfn.SWITCH( _xlpm.m, 2,IF(_xlpm.d<15,5%,7.5%), 3,IF(_xlpm.d<20,-2%,1.5%), 4,IF(_xlpm.d<17,2.5%,-5%), 5,IF(_xlpm.d<22,-5%,5%), 6,-5%, 7,IF(_xlpm.d<10,15%,-5%), 8,IF(_xlpm.d<25,-15%,3%), 9,IF(_xlpm.d<25,-15%,3%), 10,IF(_xlpm.d<11,-10%,-5%), 11,IF(_xlpm.d<13,12%,6%), 12,IF(_xlpm.d<10,6%,12%) ), ROUNDUP(D9*(1+_xlpm.r),0) )} -> 420
A24: 23 | B24: =B10 -> SKU PROD B | C24: =EDATE(C10,1) -> 46066 | D24: {=_xlfn.LET( _xlpm.m,MONTH(C24), _xlpm.d,DAY(C24), _xlpm.r, _xlfn.SWITCH( _xlpm.m, 2,IF(_xlpm.d<15,5%,7.5%), 3,IF(_xlpm.d<20,-2%,1.5%), 4,IF(_xlpm.d<17,2.5%,-5%), 5,IF(_xlpm.d<22,-5%,5%), 6,-5%, 7,IF(_xlpm.d<10,15%,-5%), 8,IF(_xlpm.d<25,-15%,3%), 9,IF(_xlpm.d<25,-15%,3%), 10,IF(_xlpm.d<11,-10%,-5%), 11,IF(_xlpm.d<13,12%,6%), 12,IF(_xlpm.d<10,6%,12%) ), ROUNDUP(D10*(1+_xlpm.r),0) )} -> 630
A25: 24 | B25: =B11 -> SKU PROD D | C25: =EDATE(C11,1) -> 46070 | D25: {=_xlfn.LET( _xlpm.m,MONTH(C25), _xlpm.d,DAY(C25), _xlpm.r, _xlfn.SWITCH( _xlpm.m, 2,IF(_xlpm.d<15,5%,7.5%), 3,IF(_xlpm.d<20,-2%,1.5%), 4,IF(_xlpm.d<17,2.5%,-5%), 5,IF(_xlpm.d<22,-5%,5%), 6,-5%, 7,IF(_xlpm.d<10,15%,-5%), 8,IF(_xlpm.d<25,-15%,3%), 9,IF(_xlpm.d<25,-15%,3%), 10,IF(_xlpm.d<11,-10%,-5%), 11,IF(_xlpm.d<13,12%,6%), 12,IF(_xlpm.d<10,6%,12%) ), ROUNDUP(D11*(1+_xlpm.r),0) )} -> 968
A26: 25 | B26: =B12 -> SKU PROD C | C26: =EDATE(C12,1) -> 46073 | D26: {=_xlfn.LET( _xlpm.m,MONTH(C26), _xlpm.d,DAY(C26), _xlpm.r, _xlfn.SWITCH( _xlpm.m, 2,IF(_xlpm.d<15,5%,7.5%), 3,IF(_xlpm.d<20,-2%,1.5%), 4,IF(_xlpm.d<17,2.5%,-5%), 5,IF(_xlpm.d<22,-5%,5%), 6,-5%, 7,IF(_xlpm.d<10,15%,-5%), 8,IF(_xlpm.d<25,-15%,3%), 9,IF(_xlpm.d<25,-15%,3%), 10,IF(_xlpm.d<11,-10%,-5%), 11,IF(_xlpm.d<13,12%,6%), 12,IF(_xlpm.d<10,6%,12%) ), ROUNDUP(D12*(1+_xlpm.r),0) )} -> 860
A27: 26 | B27: =B13 -> SKU PROD A | C27: =EDATE(C13,1) -> 46077 | D27: {=_xlfn.LET( _xlpm.m,MONTH(C27), _xlpm.d,DAY(C27), _xlpm.r, _xlfn.SWITCH( _xlpm.m, 2,IF(_xlpm.d<15,5%,7.5%), 3,IF(_xlpm.d<20,-2%,1.5%), 4,IF(_xlpm.d<17,2.5%,-5%), 5,IF(_xlpm.d<22,-5%,5%), 6,-5%, 7,IF(_xlpm.d<10,15%,-5%), 8,IF(_xlpm.d<25,-15%,3%), 9,IF(_xlpm.d<25,-15%,3%), 10,IF(_xlpm.d<11,-10%,-5%), 11,IF(_xlpm.d<13,12%,6%), 12,IF(_xlpm.d<10,6%,12%) ), ROUNDUP(D13*(1+_xlpm.r),0) )} -> 1075
... A169: 168 | B169: =B155 -> SKU PROD E | C169: =EDATE(C155,1) -> 46384 | D169: {=_xlfn.LET( _xlpm.m,MONTH(C169), _xlpm.d,DAY(C169), _xlpm.r, _xlfn.SWITCH( _xlpm.m, 2,IF(_xlpm.d<15,5%,7.5%), 3,IF(_xlpm.d<20,-2%,1.5%), 4,IF(_xlpm.d<17,2.5%,-5%), 5,IF(_xlpm.d<22,-5%,5%), 6,-5%, 7,IF(_xlpm.d<10,15%,-5%), 8,IF(_xlpm.d<25,-15%,3%), 9,IF(_xlpm.d<25,-15%,3%), 10,IF(_xlpm.d<11,-10%,-5%), 11,IF(_xlpm.d<13,12%,6%), 12,IF(_xlpm.d<10,6%,12%) ), ROUNDUP(D155*(1+_xlpm.r),0) )} -> 2357
D1048576: =SUM(D2:D1048575) -> 219178

Sheet Warehouse
A1: # | B1: Item / SKU | C1: Date | D1: Stock Qty | E1: Status
A2: 1 | B2: SKU PROD A | C2: 46023 | D2: 2200 | E2: Initial Stock | F2: =IF(C7="","",C7+3) -> 46032 | G2: 1.21
A3: 2 | B3: SKU PROD B | C3: 46023 | D3: 8000 | E3: Initial Stock | F3: =IF(C8="","",C8+3) -> 46033 | G3: 1.21
A4: 3 | B4: SKU PROD C | C4: 46023 | D4: 1700 | E4: Initial Stock | F4: =IF(C9="","",C9+3) -> 46034 | G4: 1.21
A5: 4 | B5: SKU PROD D | C5: 46023 | D5: 3500 | E5: Initial Stock | F5: =IF(C10="","",C10+3) -> 46034 | G5: 1.21
A6: 5 | B6: SKU PROD E | C6: 46023 | D6: 2300 | E6: Initial Stock | F6: =IF(C11="","",C11+3) -> 46035 | G6: 1.21
A7: 6 | B7: {=IFERROR(INDEX('Reorder Events'!$B$2:$B$200,ROWS($B$7:B7)),"")} -> SKU PROD A | C7: {=IFERROR(INDEX('Reorder Events'!$A$2:$A$200,ROWS($C$7:C7)),"")} -> 46029 | D7: {=IFERROR(INDEX('Reorder Events'!$C$2:$C$200,ROWS($D$7:D7)),"")} -> 2832 | E7: Reorder | F7: =IF(C12="","",C12+3) -> 46036 | G7: {=IF(F7="","",_xlfn.LET(_xlpm.dt,F7,_xlpm.skus,Capacity!$A$3:$A$7,_xlpm.cap,Capacity!$B$3:$B$7,SUM(_xlfn.MAP(_xlpm.skus,_xlpm.cap,_xlfn.LAMBDA(_xlpm.s,_xlpm.c,(SUMIFS(Warehouse!$D$2:$D$6,Warehouse!$B$2:$B$6,_xlpm.s)+SUMIFS(Warehouse!$D$7:$D$70,Warehouse!$B$7:$B$70,_xlpm.s,Warehouse!$F$7:$F$70,"<="&_xlpm.dt)-SUMIFS('Demand Projection'!$D$2:$D$169,'Demand Projection'!$B$2:$B$169,_xlpm.s,'Demand Projection'!$C$2:$C$169,"<="&_xlpm.dt))/_xlpm.c)))))} -> 0.7991359
A8: 7 | B8: {=IFERROR(INDEX('Reorder Events'!$B$2:$B$200,ROWS($B$7:B8)),"")} -> SKU PROD A | C8: {=IFERROR(INDEX('Reorder Events'!$A$2:$A$200,ROWS($C$7:C8)),"")} -> 46030 | D8: {=IFERROR(INDEX('Reorder Events'!$C$2:$C$200,ROWS($D$7:D8)),"")} -> 2832 | E8: Reorder | F8: =IF(C13="","",C13+3) -> 46053 | G8: {=IF(F8="","",_xlfn.LET(_xlpm.dt,F8,_xlpm.skus,Capacity!$A$3:$A$7,_xlpm.cap,Capacity!$B$3:$B$7,SUM(_xlfn.MAP(_xlpm.skus,_xlpm.cap,_xlfn.LAMBDA(_xlpm.s,_xlpm.c,(SUMIFS(Warehouse!$D$2:$D$6,Warehouse!$B$2:$B$6,_xlpm.s)+SUMIFS(Warehouse!$D$7:$D$70,Warehouse!$B$7:$B$70,_xlpm.s,Warehouse!$F$7:$F$70,"<="&_xlpm.dt)-SUMIFS('Demand Projection'!$D$2:$D$169,'Demand Projection'!$B$2:$B$169,_xlpm.s,'Demand Projection'!$C$2:$C$169,"<="&_xlpm.dt))/_xlpm.c)))))} -> 0.62213846
A9: 8 | B9: {=IFERROR(INDEX('Reorder Events'!$B$2:$B$200,ROWS($B$7:B9)),"")} -> SKU PROD A | C9: {=IFERROR(INDEX('Reorder Events'!$A$2:$A$200,ROWS($C$7:C9)),"")} -> 46031 | D9: {=IFERROR(INDEX('Reorder Events'!$C$2:$C$200,ROWS($D$7:D9)),"")} -> 2832 | E9: Reorder | F9: =IF(C14="","",C14+3) -> 46053 | G9: {=IF(F9="","",_xlfn.LET(_xlpm.dt,F9,_xlpm.skus,Capacity!$A$3:$A$7,_xlpm.cap,Capacity!$B$3:$B$7,SUM(_xlfn.MAP(_xlpm.skus,_xlpm.cap,_xlfn.LAMBDA(_xlpm.s,_xlpm.c,(SUMIFS(Warehouse!$D$2:$D$6,Warehouse!$B$2:$B$6,_xlpm.s)+SUMIFS(Warehouse!$D$7:$D$70,Warehouse!$B$7:$B$70,_xlpm.s,Warehouse!$F$7:$F$70,"<="&_xlpm.dt)-SUMIFS('Demand Projection'!$D$2:$D$169,'Demand Projection'!$B$2:$B$169,_xlpm.s,'Demand Projection'!$C$2:$C$169,"<="&_xlpm.dt))/_xlpm.c)))))} -> 0.62213846
A10: 9 | B10: {=IFERROR(INDEX('Reorder Events'!$B$2:$B$200,ROWS($B$7:B10)),"")} -> SKU PROD C | C10: {=IFERROR(INDEX('Reorder Events'!$A$2:$A$200,ROWS($C$7:C10)),"")} -> 46031 | D10: {=IFERROR(INDEX('Reorder Events'!$C$2:$C$200,ROWS($D$7:D10)),"")} -> TRUE | E10: Reorder | F10: =IF(C15="","",C15+3) -> 46054 | G10: {=IF(F10="","",_xlfn.LET(_xlpm.dt,F10,_xlpm.skus,Capacity!$A$3:$A$7,_xlpm.cap,Capacity!$B$3:$B$7,SUM(_xlfn.MAP(_xlpm.skus,_xlpm.cap,_xlfn.LAMBDA(_xlpm.s,_xlpm.c,(SUMIFS(Warehouse!$D$2:$D$6,Warehouse!$B$2:$B$6,_xlpm.s)+SUMIFS(Warehouse!$D$7:$D$70,Warehouse!$B$7:$B$70,_xlpm.s,Warehouse!$F$7:$F$70,"<="&_xlpm.dt)-SUMIFS('Demand Projection'!$D$2:$D$169,'Demand Projection'!$B$2:$B$169,_xlpm.s,'Demand Projection'!$C$2:$C$169,"<="&_xlpm.dt))/_xlpm.c)))))} -> 0.62213846
A11: 10 | B11: {=IFERROR(INDEX('Reorder Events'!$B$2:$B$200,ROWS($B$7:B11)),"")} -> SKU PROD C | C11: {=IFERROR(INDEX('Reorder Events'!$A$2:$A$200,ROWS($C$7:C11)),"")} -> 46032 | D11: {=IFERROR(INDEX('Reorder Events'!$C$2:$C$200,ROWS($D$7:D11)),"")} -> TRUE | E11: Reorder | F11: =IF(C16="","",C16+3) -> 46054 | G11: {=IF(F11="","",_xlfn.LET(_xlpm.dt,F11,_xlpm.skus,Capacity!$A$3:$A$7,_xlpm.cap,Capacity!$B$3:$B$7,SUM(_xlfn.MAP(_xlpm.skus,_xlpm.cap,_xlfn.LAMBDA(_xlpm.s,_xlpm.c,(SUMIFS(Warehouse!$D$2:$D$6,Warehouse!$B$2:$B$6,_xlpm.s)+SUMIFS(Warehouse!$D$7:$D$70,Warehouse!$B$7:$B$70,_xlpm.s,Warehouse!$F$7:$F$70,"<="&_xlpm.dt)-SUMIFS('Demand Projection'!$D$2:$D$169,'Demand Projection'!$B$2:$B$169,_xlpm.s,'Demand Projection'!$C$2:$C$169,"<="&_xlpm.dt))/_xlpm.c)))))} -> 0.62213846
A12: 11 | B12: {=IFERROR(INDEX('Reorder Events'!$B$2:$B$200,ROWS($B$7:B12)),"")} -> SKU PROD C | C12: {=IFERROR(INDEX('Reorder Events'!$A$2:$A$200,ROWS($C$7:C12)),"")} -> 46033 | D12: {=IFERROR(INDEX('Reorder Events'!$C$2:$C$200,ROWS($D$7:D12)),"")} -> TRUE | E12: Reorder | F12: =IF(C17="","",C17+3) -> 46055 | G12: {=IF(F12="","",_xlfn.LET(_xlpm.dt,F12,_xlpm.skus,Capacity!$A$3:$A$7,_xlpm.cap,Capacity!$B$3:$B$7,SUM(_xlfn.MAP(_xlpm.skus,_xlpm.cap,_xlfn.LAMBDA(_xlpm.s,_xlpm.c,(SUMIFS(Warehouse!$D$2:$D$6,Warehouse!$B$2:$B$6,_xlpm.s)+SUMIFS(Warehouse!$D$7:$D$70,Warehouse!$B$7:$B$70,_xlpm.s,Warehouse!$F$7:$F$70,"<="&_xlpm.dt)-SUMIFS('Demand Projection'!$D$2:$D$169,'Demand Projection'!$B$2:$B$169,_xlpm.s,'Demand Projection'!$C$2:$C$169,"<="&_xlpm.dt))/_xlpm.c)))))} -> 1.1563885
A13: 12 | B13: {=IFERROR(INDEX('Reorder Events'!$B$2:$B$200,ROWS($B$7:B13)),"")} -> SKU PROD D | C13: {=IFERROR(INDEX('Reorder Events'!$A$2:$A$200,ROWS($C$7:C13)),"")} -> 46050 | D13: {=IFERROR(INDEX('Reorder Events'!$C$2:$C$200,ROWS($D$7:D13)),"")} -> 4274 | E13: Reorder | F13: =IF(C18="","",C18+3) -> 46055 | G13: {=IF(F13="","",_xlfn.LET(_xlpm.dt,F13,_xlpm.skus,Capacity!$A$3:$A$7,_xlpm.cap,Capacity!$B$3:$B$7,SUM(_xlfn.MAP(_xlpm.skus,_xlpm.cap,_xlfn.LAMBDA(_xlpm.s,_xlpm.c,(SUMIFS(Warehouse!$D$2:$D$6,Warehouse!$B$2:$B$6,_xlpm.s)+SUMIFS(Warehouse!$D$7:$D$70,Warehouse!$B$7:$B$70,_xlpm.s,Warehouse!$F$7:$F$70,"<="&_xlpm.dt)-SUMIFS('Demand Projection'!$D$2:$D$169,'Demand Projection'!$B$2:$B$169,_xlpm.s,'Demand Projection'!$C$2:$C$169,"<="&_xlpm.dt))/_xlpm.c)))))} -> 1.1563885
A14: 13 | B14: {=IFERROR(INDEX('Reorder Events'!$B$2:$B$200,ROWS($B$7:B14)),"")} -> SKU PROD E | C14: {=IFERROR(INDEX('Reorder Events'!$A$2:$A$200,ROWS($C$7:C14)),"")} -> 46050 | D14: {=IFERROR(INDEX('Reorder Events'!$C$2:$C$200,ROWS($D$7:D14)),"")} -> 2283 | E14: Reorder | F14: =IF(C19="","",C19+3) -> 46059 | G14: {=IF(F14="","",_xlfn.LET(_xlpm.dt,F14,_xlpm.skus,Capacity!$A$3:$A$7,_xlpm.cap,Capacity!$B$3:$B$7,SUM(_xlfn.MAP(_xlpm.skus,_xlpm.cap,_xlfn.LAMBDA(_xlpm.s,_xlpm.c,(SUMIFS(Warehouse!$D$2:$D$6,Warehouse!$B$2:$B$6,_xlpm.s)+SUMIFS(Warehouse!$D$7:$D$70,Warehouse!$B$7:$B$70,_xlpm.s,Warehouse!$F$7:$F$70,"<="&_xlpm.dt)-SUMIFS('Demand Projection'!$D$2:$D$169,'Demand Projection'!$B$2:$B$169,_xlpm.s,'Demand Projection'!$C$2:$C$169,"<="&_xlpm.dt))/_xlpm.c)))))} -> 0.73271538
A15: 14 | B15: {=IFERROR(INDEX('Reorder Events'!$B$2:$B$200,ROWS($B$7:B15)),"")} -> SKU PROD D | C15: {=IFERROR(INDEX('Reorder Events'!$A$2:$A$200,ROWS($C$7:C15)),"")} -> 46051 | D15: {=IFERROR(INDEX('Reorder Events'!$C$2:$C$200,ROWS($D$7:D15)),"")} -> 4274 | E15: Reorder | F15: =IF(C20="","",C20+3) -> 46060 | G15: {=IF(F15="","",_xlfn.LET(_xlpm.dt,F15,_xlpm.skus,Capacity!$A$3:$A$7,_xlpm.cap,Capacity!$B$3:$B$7,SUM(_xlfn.MAP(_xlpm.skus,_xlpm.cap,_xlfn.LAMBDA(_xlpm.s,_xlpm.c,(SUMIFS(Warehouse!$D$2:$D$6,Warehouse!$B$2:$B$6,_xlpm.s)+SUMIFS(Warehouse!$D$7:$D$70,Warehouse!$B$7:$B$70,_xlpm.s,Warehouse!$F$7:$F$70,"<="&_xlpm.dt)-SUMIFS('Demand Projection'!$D$2:$D$169,'Demand Projection'!$B$2:$B$169,_xlpm.s,'Demand Projection'!$C$2:$C$169,"<="&_xlpm.dt))/_xlpm.c)))))} -> 1.1619654
A16: 15 | B16: {=IFERROR(INDEX('Reorder Events'!$B$2:$B$200,ROWS($B$7:B16)),"")} -> SKU PROD E | C16: {=IFERROR(INDEX('Reorder Events'!$A$2:$A$200,ROWS($C$7:C16)),"")} -> 46051 | D16: {=IFERROR(INDEX('Reorder Events'!$C$2:$C$200,ROWS($D$7:D16)),"")} -> 2283 | E16: Reorder | F16: =IF(C21="","",C21+3) -> 46061 | G16: {=IF(F16="","",_xlfn.LET(_xlpm.dt,F16,_xlpm.skus,Capacity!$A$3:$A$7,_xlpm.cap,Capacity!$B$3:$B$7,SUM(_xlfn.MAP(_xlpm.skus,_xlpm.cap,_xlfn.LAMBDA(_xlpm.s,_xlpm.c,(SUMIFS(Warehouse!$D$2:$D$6,Warehouse!$B$2:$B$6,_xlpm.s)+SUMIFS(Warehouse!$D$7:$D$70,Warehouse!$B$7:$B$70,_xlpm.s,Warehouse!$F$7:$F$70,"<="&_xlpm.dt)-SUMIFS('Demand Projection'!$D$2:$D$169,'Demand Projection'!$B$2:$B$169,_xlpm.s,'Demand Projection'!$C$2:$C$169,"<="&_xlpm.dt))/_xlpm.c)))))} -> 1.2790423
A17: 16 | B17: {=IFERROR(INDEX('Reorder Events'!$B$2:$B$200,ROWS($B$7:B17)),"")} -> SKU PROD D | C17: {=IFERROR(INDEX('Reorder Events'!$A$2:$A$200,ROWS($C$7:C17)),"")} -> 46052 | D17: {=IFERROR(INDEX('Reorder Events'!$C$2:$C$200,ROWS($D$7:D17)),"")} -> 4274 | E17: Reorder | F17: =IF(C22="","",C22+3) -> 46089 | G17: {=IF(F17="","",_xlfn.LET(_xlpm.dt,F17,_xlpm.skus,Capacity!$A$3:$A$7,_xlpm.cap,Capacity!$B$3:$B$7,SUM(_xlfn.MAP(_xlpm.skus,_xlpm.cap,_xlfn.LAMBDA(_xlpm.s,_xlpm.c,(SUMIFS(Warehouse!$D$2:$D$6,Warehouse!$B$2:$B$6,_xlpm.s)+SUMIFS(Warehouse!$D$7:$D$70,Warehouse!$B$7:$B$70,_xlpm.s,Warehouse!$F$7:$F$70,"<="&_xlpm.dt)-SUMIFS('Demand Projection'!$D$2:$D$169,'Demand Projection'!$B$2:$B$169,_xlpm.s,'Demand Projection'!$C$2:$C$169,"<="&_xlpm.dt))/_xlpm.c)))))} -> 0.2993291
A18: 17 | B18: {=IFERROR(INDEX('Reorder Events'!$B$2:$B$200,ROWS($B$7:B18)),"")} -> SKU PROD E | C18: {=IFERROR(INDEX('Reorder Events'!$A$2:$A$200,ROWS($C$7:C18)),"")} -> 46052 | D18: {=IFERROR(INDEX('Reorder Events'!$C$2:$C$200,ROWS($D$7:D18)),"")} -> 2283 | E18: Reorder | F18: =IF(C23="","",C23+3) -> 46090 | G18: {=IF(F18="","",_xlfn.LET(_xlpm.dt,F18,_xlpm.skus,Capacity!$A$3:$A$7,_xlpm.cap,Capacity!$B$3:$B$7,SUM(_xlfn.MAP(_xlpm.skus,_xlpm.cap,_xlfn.LAMBDA(_xlpm.s,_xlpm.c,(SUMIFS(Warehouse!$D$2:$D$6,Warehouse!$B$2:$B$6,_xlpm.s)+SUMIFS(Warehouse!$D$7:$D$70,Warehouse!$B$7:$B$70,_xlpm.s,Warehouse!$F$7:$F$70,"<="&_xlpm.dt)-SUMIFS('Demand Projection'!$D$2:$D$169,'Demand Projection'!$B$2:$B$169,_xlpm.s,'Demand Projection'!$C$2:$C$169,"<="&_xlpm.dt))/_xlpm.c)))))} -> 0.38207269
... A70: 69 | B70: {=IFERROR(INDEX('Reorder Events'!$B$2:$B$200,ROWS($B$7:B70)),"")} -> 0 | C70: {=IFERROR(INDEX('Reorder Events'!$A$2:$A$200,ROWS($C$7:C70)),"")} -> 0 | D70: {=IFERROR(INDEX('Reorder Events'!$C$2:$C$200,ROWS($D$7:D70)),"")} -> 0 | E70: Reorder | F70: =IF(C75="","",C75+3) | G70: {=IF(F70="","",_xlfn.LET(_xlpm.dt,F70,_xlpm.skus,Capacity!$A$3:$A$7,_xlpm.cap,Capacity!$B$3:$B$7,SUM(_xlfn.MAP(_xlpm.skus,_xlpm.cap,_xlfn.LAMBDA(_xlpm.s,_xlpm.c,(SUMIFS(Warehouse!$D$2:$D$6,Warehouse!$B$2:$B$6,_xlpm.s)+SUMIFS(Warehouse!$D$7:$D$70,Warehouse!$B$7:$B$70,_xlpm.s,Warehouse!$F$7:$F$70,"<="&_xlpm.dt)-SUMIFS('Demand Projection'!$D$2:$D$169,'Demand Projection'!$B$2:$B$169,_xlpm.s,'Demand Projection'!$C$2:$C$169,"<="&_xlpm.dt))/_xlpm.c)))))}

Sheet Capacity
A1: Warehouse Capacity | D1: Min/Max Stock Level
A2: Product | B2: Full Unit Capacity | D2: Product | E2: Min | F2: Max
A3: SKU PROD A | B3: 10000 | D3: SKU PROD A | E3: {=_xlfn.LET(_xlpm.sku,$D3,_xlpm.dates,_xlfn._xlws.FILTER('Demand Projection'!$C$2:$C$169,('Demand Projection'!$B$2:$B$169=_xlpm.sku)*('Demand Projection'!$C$2:$C$169<=DATE(2026,12,26))),_xlpm.roll,_xlfn.MAP(_xlpm.dates,_xlfn.LAMBDA(_xlpm.d,SUMIFS('Demand Projection'!$D$2:$D$169,'Demand Projection'!$B$2:$B$169,_xlpm.sku,'Demand Projection'!$C$2:$C$169,">="&_xlpm.d,'Demand Projection'!$C$2:$C$169,"<="&_xlpm.d+5))),MIN(_xlpm.roll))} -> 678 | F3: {=_xlfn.LET(_xlpm.sku,$D3,_xlpm.dates,_xlfn._xlws.FILTER('Demand Projection'!$C$2:$C$169,('Demand Projection'!$B$2:$B$169=_xlpm.sku)*('Demand Projection'!$C$2:$C$169<=DATE(2026,12,26))),_xlpm.roll,_xlfn.MAP(_xlpm.dates,_xlfn.LAMBDA(_xlpm.d,SUMIFS('Demand Projection'!$D$2:$D$169,'Demand Projection'!$B$2:$B$169,_xlpm.sku,'Demand Projection'!$C$2:$C$169,">="&_xlpm.d,'Demand Projection'!$C$2:$C$169,"<="&_xlpm.d+5))),MAX(_xlpm.roll))} -> 2632
A4: SKU PROD B | B4: 25000 | D4: SKU PROD B | E4: {=_xlfn.LET(_xlpm.sku,$D4,_xlpm.dates,_xlfn._xlws.FILTER('Demand Projection'!$C$2:$C$169,('Demand Projection'!$B$2:$B$169=_xlpm.sku)*('Demand Projection'!$C$2:$C$169<=DATE(2026,12,26))),_xlpm.roll,_xlfn.MAP(_xlpm.dates,_xlfn.LAMBDA(_xlpm.d,SUMIFS('Demand Projection'!$D$2:$D$169,'Demand Projection'!$B$2:$B$169,_xlpm.sku,'Demand Projection'!$C$2:$C$169,">="&_xlpm.d,'Demand Projection'!$C$2:$C$169,"<="&_xlpm.d+5))),MIN(_xlpm.roll))} -> 376 | F4: {=_xlfn.LET(_xlpm.sku,$D4,_xlpm.dates,_xlfn._xlws.FILTER('Demand Projection'!$C$2:$C$169,('Demand Projection'!$B$2:$B$169=_xlpm.sku)*('Demand Projection'!$C$2:$C$169<=DATE(2026,12,26))),_xlpm.roll,_xlfn.MAP(_xlpm.dates,_xlfn.LAMBDA(_xlpm.d,SUMIFS('Demand Projection'!$D$2:$D$169,'Demand Projection'!$B$2:$B$169,_xlpm.sku,'Demand Projection'!$C$2:$C$169,">="&_xlpm.d,'Demand Projection'!$C$2:$C$169,"<="&_xlpm.d+5))),MAX(_xlpm.roll))} -> 6570
A5: SKU PROD C | B5: 15000 | D5: SKU PROD C | E5: {=_xlfn.LET(_xlpm.sku,$D5,_xlpm.dates,_xlfn._xlws.FILTER('Demand Projection'!$C$2:$C$169,('Demand Projection'!$B$2:$B$169=_xlpm.sku)*('Demand Projection'!$C$2:$C$169<=DATE(2026,12,26))),_xlpm.roll,_xlfn.MAP(_xlpm.dates,_xlfn.LAMBDA(_xlpm.d,SUMIFS('Demand Projection'!$D$2:$D$169,'Demand Projection'!$B$2:$B$169,_xlpm.sku,'Demand Projection'!$C$2:$C$169,">="&_xlpm.d,'Demand Projection'!$C$2:$C$169,"<="&_xlpm.d+5))),MIN(_xlpm.roll))} -> 358 | F5: {=_xlfn.LET(_xlpm.sku,$D5,_xlpm.dates,_xlfn._xlws.FILTER('Demand Projection'!$C$2:$C$169,('Demand Projection'!$B$2:$B$169=_xlpm.sku)*('Demand Projection'!$C$2:$C$169<=DATE(2026,12,26))),_xlpm.roll,_xlfn.MAP(_xlpm.dates,_xlfn.LAMBDA(_xlpm.d,SUMIFS('Demand Projection'!$D$2:$D$169,'Demand Projection'!$B$2:$B$169,_xlpm.sku,'Demand Projection'!$C$2:$C$169,">="&_xlpm.d,'Demand Projection'!$C$2:$C$169,"<="&_xlpm.d+5))),MAX(_xlpm.roll))} -> 1537
A6: SKU PROD D | B6: 8000 | D6: SKU PROD D | E6: {=_xlfn.LET(_xlpm.sku,$D6,_xlpm.dates,_xlfn._xlws.FILTER('Demand Projection'!$C$2:$C$169,('Demand Projection'!$B$2:$B$169=_xlpm.sku)*('Demand Projection'!$C$2:$C$169<=DATE(2026,12,26))),_xlpm.roll,_xlfn.MAP(_xlpm.dates,_xlfn.LAMBDA(_xlpm.d,SUMIFS('Demand Projection'!$D$2:$D$169,'Demand Projection'!$B$2:$B$169,_xlpm.sku,'Demand Projection'!$C$2:$C$169,">="&_xlpm.d,'Demand Projection'!$C$2:$C$169,"<="&_xlpm.d+5))),MIN(_xlpm.roll))} -> 430 | F6: {=_xlfn.LET(_xlpm.sku,$D6,_xlpm.dates,_xlfn._xlws.FILTER('Demand Projection'!$C$2:$C$169,('Demand Projection'!$B$2:$B$169=_xlpm.sku)*('Demand Projection'!$C$2:$C$169<=DATE(2026,12,26))),_xlpm.roll,_xlfn.MAP(_xlpm.dates,_xlfn.LAMBDA(_xlpm.d,SUMIFS('Demand Projection'!$D$2:$D$169,'Demand Projection'!$B$2:$B$169,_xlpm.sku,'Demand Projection'!$C$2:$C$169,">="&_xlpm.d,'Demand Projection'!$C$2:$C$169,"<="&_xlpm.d+5))),MAX(_xlpm.roll))} -> 3274
A7: SKU PROD E | B7: 19500 | D7: SKU PROD E | E7: {=_xlfn.LET(_xlpm.sku,$D7,_xlpm.dates,_xlfn._xlws.FILTER('Demand Projection'!$C$2:$C$169,('Demand Projection'!$B$2:$B$169=_xlpm.sku)*('Demand Projection'!$C$2:$C$169<=DATE(2026,12,26))),_xlpm.roll,_xlfn.MAP(_xlpm.dates,_xlfn.LAMBDA(_xlpm.d,SUMIFS('Demand Projection'!$D$2:$D$169,'Demand Projection'!$B$2:$B$169,_xlpm.sku,'Demand Projection'!$C$2:$C$169,">="&_xlpm.d,'Demand Projection'!$C$2:$C$169,"<="&_xlpm.d+5))),MIN(_xlpm.roll))} -> 250 | F7: {=_xlfn.LET(_xlpm.sku,$D7,_xlpm.dates,_xlfn._xlws.FILTER('Demand Projection'!$C$2:$C$169,('Demand Projection'!$B$2:$B$169=_xlpm.sku)*('Demand Projection'!$C$2:$C$169<=DATE(2026,12,26))),_xlpm.roll,_xlfn.MAP(_xlpm.dates,_xlfn.LAMBDA(_xlpm.d,SUMIFS('Demand Projection'!$D$2:$D$169,'Demand Projection'!$B$2:$B$169,_xlpm.sku,'Demand Projection'!$C$2:$C$169,">="&_xlpm.d,'Demand Projection'!$C$2:$C$169,"<="&_xlpm.d+5))),MAX(_xlpm.roll))} -> 2183

Sheet Reorder Calc
A1: Date | B1: SKU PROD A | C1: SKU PROD B | D1: SKU PROD C | E1: SKU PROD D | F1: SKU PROD E | G1: SKU PROD A | H1: SKU PROD B | I1: SKU PROD C | J1: SKU PROD D | K1: SKU PROD E | L1: SKU PROD A | M1: SKU PROD B | N1: SKU PROD C | O1: SKU PROD D | P1: SKU PROD E | Q1: SKU PROD A | R1: SKU PROD B | S1: SKU PROD C | T1: SKU PROD D | U1: SKU PROD E
A2: =DATE(2026,1,1) -> 46023 | B2: =SUMIFS('Demand Projection'!$D$2:$D$169,'Demand Projection'!$B$2:$B$169,B$1,'Demand Projection'!$C$2:$C$169,$A2) -> 0 | C2: =SUMIFS('Demand Projection'!$D$2:$D$169,'Demand Projection'!$B$2:$B$169,C$1,'Demand Projection'!$C$2:$C$169,$A2) -> 0 | D2: =SUMIFS('Demand Projection'!$D$2:$D$169,'Demand Projection'!$B$2:$B$169,D$1,'Demand Projection'!$C$2:$C$169,$A2) -> 0 | E2: =SUMIFS('Demand Projection'!$D$2:$D$169,'Demand Projection'!$B$2:$B$169,E$1,'Demand Projection'!$C$2:$C$169,$A2) -> 0 | F2: =SUMIFS('Demand Projection'!$D$2:$D$169,'Demand Projection'!$B$2:$B$169,F$1,'Demand Projection'!$C$2:$C$169,$A2) -> 0 | G2: =_xlfn.XLOOKUP(G$1,Capacity!$D$3:$D$7,Warehouse!$D$2:$D$6) -> 2200 | H2: =_xlfn.XLOOKUP(H$1,Capacity!$D$3:$D$7,Warehouse!$D$2:$D$6) -> 8000 | I2: =_xlfn.XLOOKUP(I$1,Capacity!$D$3:$D$7,Warehouse!$D$2:$D$6) -> 1700 | J2: =_xlfn.XLOOKUP(J$1,Capacity!$D$3:$D$7,Warehouse!$D$2:$D$6) -> 3500 | K2: =_xlfn.XLOOKUP(K$1,Capacity!$D$3:$D$7,Warehouse!$D$2:$D$6) -> 2300 | L2: =IF(Q2<_xlfn.XLOOKUP(L$1,Capacity!$D$3:$D$7,Capacity!$E$3:$E$7),_xlfn.XLOOKUP(L$1,Capacity!$D$3:$D$7,Capacity!$F$3:$F$7)-Q2,0) -> 0 | M2: =IF(R2<_xlfn.XLOOKUP(M$1,Capacity!$D$3:$D$7,Capacity!$E$3:$E$7),_xlfn.XLOOKUP(M$1,Capacity!$D$3:$D$7,Capacity!$F$3:$F$7)-R2,0) -> 0 | N2: =IF(S2<_xlfn.XLOOKUP(N$1,Capacity!$D$3:$D$7,Capacity!$E$3:$E$7),_xlfn.XLOOKUP(N$1,Capacity!$D$3:$D$7,Capacity!$F$3:$F$7)-S2,0) -> 0 | O2: =IF(T2<_xlfn.XLOOKUP(O$1,Capacity!$D$3:$D$7,Capacity!$E$3:$E$7),_xlfn.XLOOKUP(O$1,Capacity!$D$3:$D$7,Capacity!$F$3:$F$7)-T2,0) -> 0 | P2: =IF(U2<_xlfn.XLOOKUP(P$1,Capacity!$D$3:$D$7,Capacity!$E$3:$E$7),_xlfn.XLOOKUP(P$1,Capacity!$D$3:$D$7,Capacity!$F$3:$F$7)-U2,0) -> 0 | Q2: =G2-B2 -> 2200 | R2: =H2-C2 -> 8000 | S2: =I2-D2 -> 1700 | T2: =J2-E2 -> 3500 | U2: =K2-F2 -> 2300
A3: =A2+1 -> 46024 | B3: =SUMIFS('Demand Projection'!$D$2:$D$169,'Demand Projection'!$B$2:$B$169,B$1,'Demand Projection'!$C$2:$C$169,$A3) -> 0 | C3: =SUMIFS('Demand Projection'!$D$2:$D$169,'Demand Projection'!$B$2:$B$169,C$1,'Demand Projection'!$C$2:$C$169,$A3) -> 0 | D3: =SUMIFS('Demand Projection'!$D$2:$D$169,'Demand Projection'!$B$2:$B$169,D$1,'Demand Projection'!$C$2:$C$169,$A3) -> 0 | E3: =SUMIFS('Demand Projection'!$D$2:$D$169,'Demand Projection'!$B$2:$B$169,E$1,'Demand Projection'!$C$2:$C$169,$A3) -> 0 | F3: =SUMIFS('Demand Projection'!$D$2:$D$169,'Demand Projection'!$B$2:$B$169,F$1,'Demand Projection'!$C$2:$C$169,$A3) -> 0 | G3: {=Q2+IF(ROW()-3<2,0,INDEX(L:L,ROW()-3))} -> 2200 | H3: {=R2+IF(ROW()-3<2,0,INDEX(M:M,ROW()-3))} -> 8000 | I3: {=S2+IF(ROW()-3<2,0,INDEX(N:N,ROW()-3))} -> 1700 | J3: {=T2+IF(ROW()-3<2,0,INDEX(O:O,ROW()-3))} -> 3500 | K3: {=U2+IF(ROW()-3<2,0,INDEX(P:P,ROW()-3))} -> 2300 | L3: =IF(Q3<_xlfn.XLOOKUP(L$1,Capacity!$D$3:$D$7,Capacity!$E$3:$E$7),_xlfn.XLOOKUP(L$1,Capacity!$D$3:$D$7,Capacity!$F$3:$F$7)-Q3,0) -> 0 | M3: =IF(R3<_xlfn.XLOOKUP(M$1,Capacity!$D$3:$D$7,Capacity!$E$3:$E$7),_xlfn.XLOOKUP(M$1,Capacity!$D$3:$D$7,Capacity!$F$3:$F$7)-R3,0) -> 0 | N3: =IF(S3<_xlfn.XLOOKUP(N$1,Capacity!$D$3:$D$7,Capacity!$E$3:$E$7),_xlfn.XLOOKUP(N$1,Capacity!$D$3:$D$7,Capacity!$F$3:$F$7)-S3,0) -> 0 | O3: =IF(T3<_xlfn.XLOOKUP(O$1,Capacity!$D$3:$D$7,Capacity!$E$3:$E$7),_xlfn.XLOOKUP(O$1,Capacity!$D$3:$D$7,Capacity!$F$3:$F$7)-T3,0) -> 0 | P3: =IF(U3<_xlfn.XLOOKUP(P$1,Capacity!$D$3:$D$7,Capacity!$E$3:$E$7),_xlfn.XLOOKUP(P$1,Capacity!$D$3:$D$7,Capacity!$F$3:$F$7)-U3,0) -> 0 | Q3: =G3-B3 -> 2200 | R3: =H3-C3 -> 8000 | S3: =I3-D3 -> 1700 | T3: =J3-E3 -> 3500 | U3: =K3-F3 -> 2300
A4: =A3+1 -> 46025 | B4: =SUMIFS('Demand Projection'!$D$2:$D$169,'Demand Projection'!$B$2:$B$169,B$1,'Demand Projection'!$C$2:$C$169,$A4) -> 1000 | C4: =SUMIFS('Demand Projection'!$D$2:$D$169,'Demand Projection'!$B$2:$B$169,C$1,'Demand Projection'!$C$2:$C$169,$A4) -> 6000 | D4: =SUMIFS('Demand Projection'!$D$2:$D$169,'Demand Projection'!$B$2:$B$169,D$1,'Demand Projection'!$C$2:$C$169,$A4) -> 0 | E4: =SUMIFS('Demand Projection'!$D$2:$D$169,'Demand Projection'!$B$2:$B$169,E$1,'Demand Projection'!$C$2:$C$169,$A4) -> 0 | F4: =SUMIFS('Demand Projection'!$D$2:$D$169,'Demand Projection'!$B$2:$B$169,F$1,'Demand Projection'!$C$2:$C$169,$A4) -> 0 | G4: {=Q3+IF(ROW()-3<2,0,INDEX(L:L,ROW()-3))} -> 2200 | H4: {=R3+IF(ROW()-3<2,0,INDEX(M:M,ROW()-3))} -> 8000 | I4: {=S3+IF(ROW()-3<2,0,INDEX(N:N,ROW()-3))} -> 1700 | J4: {=T3+IF(ROW()-3<2,0,INDEX(O:O,ROW()-3))} -> 3500 | K4: {=U3+IF(ROW()-3<2,0,INDEX(P:P,ROW()-3))} -> 2300 | L4: =IF(Q4<_xlfn.XLOOKUP(L$1,Capacity!$D$3:$D$7,Capacity!$E$3:$E$7),_xlfn.XLOOKUP(L$1,Capacity!$D$3:$D$7,Capacity!$F$3:$F$7)-Q4,0) -> 0 | M4: =IF(R4<_xlfn.XLOOKUP(M$1,Capacity!$D$3:$D$7,Capacity!$E$3:$E$7),_xlfn.XLOOKUP(M$1,Capacity!$D$3:$D$7,Capacity!$F$3:$F$7)-R4,0) -> 0 | N4: =IF(S4<_xlfn.XLOOKUP(N$1,Capacity!$D$3:$D$7,Capacity!$E$3:$E$7),_xlfn.XLOOKUP(N$1,Capacity!$D$3:$D$7,Capacity!$F$3:$F$7)-S4,0) -> 0 | O4: =IF(T4<_xlfn.XLOOKUP(O$1,Capacity!$D$3:$D$7,Capacity!$E$3:$E$7),_xlfn.XLOOKUP(O$1,Capacity!$D$3:$D$7,Capacity!$F$3:$F$7)-T4,0) -> 0 | P4: =IF(U4<_xlfn.XLOOKUP(P$1,Capacity!$D$3:$D$7,Capacity!$E$3:$E$7),_xlfn.XLOOKUP(P$1,Capacity!$D$3:$D$7,Capacity!$F$3:$F$7)-U4,0) -> 0 | Q4: =G4-B4 -> 1200 | R4: =H4-C4 -> 2000 | S4: =I4-D4 -> 1700 | T4: =J4-E4 -> 3500 | U4: =K4-F4 -> 2300
A5: =A4+1 -> 46026 | B5: =SUMIFS('Demand Projection'!$D$2:$D$169,'Demand Projection'!$B$2:$B$169,B$1,'Demand Projection'!$C$2:$C$169,$A5) -> 400 | C5: =SUMIFS('Demand Projection'!$D$2:$D$169,'Demand Projection'!$B$2:$B$169,C$1,'Demand Projection'!$C$2:$C$169,$A5) -> 0 | D5: =SUMIFS('Demand Projection'!$D$2:$D$169,'Demand Projection'!$B$2:$B$169,D$1,'Demand Projection'!$C$2:$C$169,$A5) -> 0 | E5: =SUMIFS('Demand Projection'!$D$2:$D$169,'Demand Projection'!$B$2:$B$169,E$1,'Demand Projection'!$C$2:$C$169,$A5) -> 0 | F5: =SUMIFS('Demand Projection'!$D$2:$D$169,'Demand Projection'!$B$2:$B$169,F$1,'Demand Projection'!$C$2:$C$169,$A5) -> 0 | G5: {=Q4+IF(ROW()-3<2,0,INDEX(L:L,ROW()-3))} -> 1200 | H5: {=R4+IF(ROW()-3<2,0,INDEX(M:M,ROW()-3))} -> 2000 | I5: {=S4+IF(ROW()-3<2,0,INDEX(N:N,ROW()-3))} -> 1700 | J5: {=T4+IF(ROW()-3<2,0,INDEX(O:O,ROW()-3))} -> 3500 | K5: {=U4+IF(ROW()-3<2,0,INDEX(P:P,ROW()-3))} -> 2300 | L5: =IF(Q5<_xlfn.XLOOKUP(L$1,Capacity!$D$3:$D$7,Capacity!$E$3:$E$7),_xlfn.XLOOKUP(L$1,Capacity!$D$3:$D$7,Capacity!$F$3:$F$7)-Q5,0) -> 0 | M5: =IF(R5<_xlfn.XLOOKUP(M$1,Capacity!$D$3:$D$7,Capacity!$E$3:$E$7),_xlfn.XLOOKUP(M$1,Capacity!$D$3:$D$7,Capacity!$F$3:$F$7)-R5,0) -> 0 | N5: =IF(S5<_xlfn.XLOOKUP(N$1,Capacity!$D$3:$D$7,Capacity!$E$3:$E$7),_xlfn.XLOOKUP(N$1,Capacity!$D$3:$D$7,Capacity!$F$3:$F$7)-S5,0) -> 0 | O5: =IF(T5<_xlfn.XLOOKUP(O$1,Capacity!$D$3:$D$7,Capacity!$E$3:$E$7),_xlfn.XLOOKUP(O$1,Capacity!$D$3:$D$7,Capacity!$F$3:$F$7)-T5,0) -> 0 | P5: =IF(U5<_xlfn.XLOOKUP(P$1,Capacity!$D$3:$D$7,Capacity!$E$3:$E$7),_xlfn.XLOOKUP(P$1,Capacity!$D$3:$D$7,Capacity!$F$3:$F$7)-U5,0) -> 0 | Q5: =G5-B5 -> 800 | R5: =H5-C5 -> 2000 | S5: =I5-D5 -> 1700 | T5: =J5-E5 -> 3500 | U5: =K5-F5 -> 2300
A6: =A5+1 -> 46027 | B6: =SUMIFS('Demand Projection'!$D$2:$D$169,'Demand Projection'!$B$2:$B$169,B$1,'Demand Projection'!$C$2:$C$169,$A6) -> 0 | C6: =SUMIFS('Demand Projection'!$D$2:$D$169,'Demand Projection'!$B$2:$B$169,C$1,'Demand Projection'!$C$2:$C$169,$A6) -> 0 | D6: =SUMIFS('Demand Projection'!$D$2:$D$169,'Demand Projection'!$B$2:$B$169,D$1,'Demand Projection'!$C$2:$C$169,$A6) -> 900 | E6: =SUMIFS('Demand Projection'!$D$2:$D$169,'Demand Projection'!$B$2:$B$169,E$1,'Demand Projection'!$C$2:$C$169,$A6) -> 0 | F6: =SUMIFS('Demand Projection'!$D$2:$D$169,'Demand Projection'!$B$2:$B$169,F$1,'Demand Projection'!$C$2:$C$169,$A6) -> 0 | G6: {=Q5+IF(ROW()-3<2,0,INDEX(L:L,ROW()-3))} -> 800 | H6: {=R5+IF(ROW()-3<2,0,INDEX(M:M,ROW()-3))} -> 2000 | I6: {=S5+IF(ROW()-3<2,0,INDEX(N:N,ROW()-3))} -> 1700 | J6: {=T5+IF(ROW()-3<2,0,INDEX(O:O,ROW()-3))} -> 3500 | K6: {=U5+IF(ROW()-3<2,0,INDEX(P:P,ROW()-3))} -> 2300 | L6: =IF(Q6<_xlfn.XLOOKUP(L$1,Capacity!$D$3:$D$7,Capacity!$E$3:$E$7),_xlfn.XLOOKUP(L$1,Capacity!$D$3:$D$7,Capacity!$F$3:$F$7)-Q6,0) -> 0 | M6: =IF(R6<_xlfn.XLOOKUP(M$1,Capacity!$D$3:$D$7,Capacity!$E$3:$E$7),_xlfn.XLOOKUP(M$1,Capacity!$D$3:$D$7,Capacity!$F$3:$F$7)-R6,0) -> 0 | N6: =IF(S6<_xlfn.XLOOKUP(N$1,Capacity!$D$3:$D$7,Capacity!$E$3:$E$7),_xlfn.XLOOKUP(N$1,Capacity!$D$3:$D$7,Capacity!$F$3:$F$7)-S6,0) -> 0 | O6: =IF(T6<_xlfn.XLOOKUP(O$1,Capacity!$D$3:$D$7,Capacity!$E$3:$E$7),_xlfn.XLOOKUP(O$1,Capacity!$D$3:$D$7,Capacity!$F$3:$F$7)-T6,0) -> 0 | P6: =IF(U6<_xlfn.XLOOKUP(P$1,Capacity!$D$3:$D$7,Capacity!$E$3:$E$7),_xlfn.XLOOKUP(P$1,Capacity!$D$3:$D$7,Capacity!$F$3:$F$7)-U6,0) -> 0 | Q6: =G6-B6 -> 800 | R6: =H6-C6 -> 2000 | S6: =I6-D6 -> 800 | T6: =J6-E6 -> 3500 | U6: =K6-F6 -> 2300
A7: =A6+1 -> 46028 | B7: =SUMIFS('Demand Projection'!$D$2:$D$169,'Demand Projection'!$B$2:$B$169,B$1,'Demand Projection'!$C$2:$C$169,$A7) -> 0 | C7: =SUMIFS('Demand Projection'!$D$2:$D$169,'Demand Projection'!$B$2:$B$169,C$1,'Demand Projection'!$C$2:$C$169,$A7) -> 0 | D7: =SUMIFS('Demand Projection'!$D$2:$D$169,'Demand Projection'!$B$2:$B$169,D$1,'Demand Projection'!$C$2:$C$169,$A7) -> 0 | E7: =SUMIFS('Demand Projection'!$D$2:$D$169,'Demand Projection'!$B$2:$B$169,E$1,'Demand Projection'!$C$2:$C$169,$A7) -> 600 | F7: =SUMIFS('Demand Projection'!$D$2:$D$169,'Demand Projection'!$B$2:$B$169,F$1,'Demand Projection'!$C$2:$C$169,$A7) -> 0 | G7: {=Q6+IF(ROW()-3<2,0,INDEX(L:L,ROW()-3))} -> 800 | H7: {=R6+IF(ROW()-3<2,0,INDEX(M:M,ROW()-3))} -> 2000 | I7: {=S6+IF(ROW()-3<2,0,INDEX(N:N,ROW()-3))} -> 800 | J7: {=T6+IF(ROW()-3<2,0,INDEX(O:O,ROW()-3))} -> 3500 | K7: {=U6+IF(ROW()-3<2,0,INDEX(P:P,ROW()-3))} -> 2300 | L7: =IF(Q7<_xlfn.XLOOKUP(L$1,Capacity!$D$3:$D$7,Capacity!$E$3:$E$7),_xlfn.XLOOKUP(L$1,Capacity!$D$3:$D$7,Capacity!$F$3:$F$7)-Q7,0) -> 0 | M7: =IF(R7<_xlfn.XLOOKUP(M$1,Capacity!$D$3:$D$7,Capacity!$E$3:$E$7),_xlfn.XLOOKUP(M$1,Capacity!$D$3:$D$7,Capacity!$F$3:$F$7)-R7,0) -> 0 | N7: =IF(S7<_xlfn.XLOOKUP(N$1,Capacity!$D$3:$D$7,Capacity!$E$3:$E$7),_xlfn.XLOOKUP(N$1,Capacity!$D$3:$D$7,Capacity!$F$3:$F$7)-S7,0) -> 0 | O7: =IF(T7<_xlfn.XLOOKUP(O$1,Capacity!$D$3:$D$7,Capacity!$E$3:$E$7),_xlfn.XLOOKUP(O$1,Capacity!$D$3:$D$7,Capacity!$F$3:$F$7)-T7,0) -> 0 | P7: =IF(U7<_xlfn.XLOOKUP(P$1,Capacity!$D$3:$D$7,Capacity!$E$3:$E$7),_xlfn.XLOOKUP(P$1,Capacity!$D$3:$D$7,Capacity!$F$3:$F$7)-U7,0) -> 0 | Q7: =G7-B7 -> 800 | R7: =H7-C7 -> 2000 | S7: =I7-D7 -> 800 | T7: =J7-E7 -> 2900 | U7: =K7-F7 -> 2300
A8: =A7+1 -> 46029 | B8: =SUMIFS('Demand Projection'!$D$2:$D$169,'Demand Projection'!$B$2:$B$169,B$1,'Demand Projection'!$C$2:$C$169,$A8) -> 1000 | C8: =SUMIFS('Demand Projection'!$D$2:$D$169,'Demand Projection'!$B$2:$B$169,C$1,'Demand Projection'!$C$2:$C$169,$A8) -> 0 | D8: =SUMIFS('Demand Projection'!$D$2:$D$169,'Demand Projection'!$B$2:$B$169,D$1,'Demand Projection'!$C$2:$C$169,$A8) -> 0 | E8: =SUMIFS('Demand Projection'!$D$2:$D$169,'Demand Projection'!$B$2:$B$169,E$1,'Demand Projection'!$C$2:$C$169,$A8) -> 0 | F8: =SUMIFS('Demand Projection'!$D$2:$D$169,'Demand Projection'!$B$2:$B$169,F$1,'Demand Projection'!$C$2:$C$169,$A8) -> 0 | G8: {=Q7+IF(ROW()-3<2,0,INDEX(L:L,ROW()-3))} -> 800 | H8: {=R7+IF(ROW()-3<2,0,INDEX(M:M,ROW()-3))} -> 2000 | I8: {=S7+IF(ROW()-3<2,0,INDEX(N:N,ROW()-3))} -> 800 | J8: {=T7+IF(ROW()-3<2,0,INDEX(O:O,ROW()-3))} -> 2900 | K8: {=U7+IF(ROW()-3<2,0,INDEX(P:P,ROW()-3))} -> 2300 | L8: =IF(Q8<_xlfn.XLOOKUP(L$1,Capacity!$D$3:$D$7,Capacity!$E$3:$E$7),_xlfn.XLOOKUP(L$1,Capacity!$D$3:$D$7,Capacity!$F$3:$F$7)-Q8,0) -> 2832 | M8: =IF(R8<_xlfn.XLOOKUP(M$1,Capacity!$D$3:$D$7,Capacity!$E$3:$E$7),_xlfn.XLOOKUP(M$1,Capacity!$D$3:$D$7,Capacity!$F$3:$F$7)-R8,0) -> 0 | N8: =IF(S8<_xlfn.XLOOKUP(N$1,Capacity!$D$3:$D$7,Capacity!$E$3:$E$7),_xlfn.XLOOKUP(N$1,Capacity!$D$3:$D$7,Capacity!$F$3:$F$7)-S8,0) -> 0 | O8: =IF(T8<_xlfn.XLOOKUP(O$1,Capacity!$D$3:$D$7,Capacity!$E$3:$E$7),_xlfn.XLOOKUP(O$1,Capacity!$D$3:$D$7,Capacity!$F$3:$F$7)-T8,0) -> 0 | P8: =IF(U8<_xlfn.XLOOKUP(P$1,Capacity!$D$3:$D$7,Capacity!$E$3:$E$7),_xlfn.XLOOKUP(P$1,Capacity!$D$3:$D$7,Capacity!$F$3:$F$7)-U8,0) -> 0 | Q8: =G8-B8 -> -200 | R8: =H8-C8 -> 2000 | S8: =I8-D8 -> 800 | T8: =J8-E8 -> 2900 | U8: =K8-F8 -> 2300
A9: =A8+1 -> 46030 | B9: =SUMIFS('Demand Projection'!$D$2:$D$169,'Demand Projection'!$B$2:$B$169,B$1,'Demand Projection'!$C$2:$C$169,$A9) -> 0 | C9: =SUMIFS('Demand Projection'!$D$2:$D$169,'Demand Projection'!$B$2:$B$169,C$1,'Demand Projection'!$C$2:$C$169,$A9) -> 0 | D9: =SUMIFS('Demand Projection'!$D$2:$D$169,'Demand Projection'!$B$2:$B$169,D$1,'Demand Projection'!$C$2:$C$169,$A9) -> 0 | E9: =SUMIFS('Demand Projection'!$D$2:$D$169,'Demand Projection'!$B$2:$B$169,E$1,'Demand Projection'!$C$2:$C$169,$A9) -> 0 | F9: =SUMIFS('Demand Projection'!$D$2:$D$169,'Demand Projection'!$B$2:$B$169,F$1,'Demand Projection'!$C$2:$C$169,$A9) -> 0 | G9: {=Q8+IF(ROW()-3<2,0,INDEX(L:L,ROW()-3))} -> -200 | H9: {=R8+IF(ROW()-3<2,0,INDEX(M:M,ROW()-3))} -> 2000 | I9: {=S8+IF(ROW()-3<2,0,INDEX(N:N,ROW()-3))} -> 800 | J9: {=T8+IF(ROW()-3<2,0,INDEX(O:O,ROW()-3))} -> 2900 | K9: {=U8+IF(ROW()-3<2,0,INDEX(P:P,ROW()-3))} -> 2300 | L9: =IF(Q9<_xlfn.XLOOKUP(L$1,Capacity!$D$3:$D$7,Capacity!$E$3:$E$7),_xlfn.XLOOKUP(L$1,Capacity!$D$3:$D$7,Capacity!$F$3:$F$7)-Q9,0) -> 2832 | M9: =IF(R9<_xlfn.XLOOKUP(M$1,Capacity!$D$3:$D$7,Capacity!$E$3:$E$7),_xlfn.XLOOKUP(M$1,Capacity!$D$3:$D$7,Capacity!$F$3:$F$7)-R9,0) -> 0 | N9: =IF(S9<_xlfn.XLOOKUP(N$1,Capacity!$D$3:$D$7,Capacity!$E$3:$E$7),_xlfn.XLOOKUP(N$1,Capacity!$D$3:$D$7,Capacity!$F$3:$F$7)-S9,0) -> 0 | O9: =IF(T9<_xlfn.XLOOKUP(O$1,Capacity!$D$3:$D$7,Capacity!$E$3:$E$7),_xlfn.XLOOKUP(O$1,Capacity!$D$3:$D$7,Capacity!$F$3:$F$7)-T9,0) -> 0 | P9: =IF(U9<_xlfn.XLOOKUP(P$1,Capacity!$D$3:$D$7,Capacity!$E$3:$E$7),_xlfn.XLOOKUP(P$1,Capacity!$D$3:$D$7,Capacity!$F$3:$F$7)-U9,0) -> 0 | Q9: =G9-B9 -> -200 | R9: =H9-C9 -> 2000 | S9: =I9-D9 -> 800 | T9: =J9-E9 -> 2900 | U9: =K9-F9 -> 2300
A10: =A9+1 -> 46031 | B10: =SUMIFS('Demand Projection'!$D$2:$D$169,'Demand Projection'!$B$2:$B$169,B$1,'Demand Projection'!$C$2:$C$169,$A10) -> 0 | C10: =SUMIFS('Demand Projection'!$D$2:$D$169,'Demand Projection'!$B$2:$B$169,C$1,'Demand Projection'!$C$2:$C$169,$A10) -> 0 | D10: =SUMIFS('Demand Projection'!$D$2:$D$169,'Demand Projection'!$B$2:$B$169,D$1,'Demand Projection'!$C$2:$C$169,$A10) -> 500 | E10: =SUMIFS('Demand Projection'!$D$2:$D$169,'Demand Projection'!$B$2:$B$169,E$1,'Demand Projection'!$C$2:$C$169,$A10) -> 0 | F10: =SUMIFS('Demand Projection'!$D$2:$D$169,'Demand Projection'!$B$2:$B$169,F$1,'Demand Projection'!$C$2:$C$169,$A10) -> 0 | G10: {=Q9+IF(ROW()-3<2,0,INDEX(L:L,ROW()-3))} -> -200 | H10: {=R9+IF(ROW()-3<2,0,INDEX(M:M,ROW()-3))} -> 2000 | I10: {=S9+IF(ROW()-3<2,0,INDEX(N:N,ROW()-3))} -> 800 | J10: {=T9+IF(ROW()-3<2,0,INDEX(O:O,ROW()-3))} -> 2900 | K10: {=U9+IF(ROW()-3<2,0,INDEX(P:P,ROW()-3))} -> 2300 | L10: =IF(Q10<_xlfn.XLOOKUP(L$1,Capacity!$D$3:$D$7,Capacity!$E$3:$E$7),_xlfn.XLOOKUP(L$1,Capacity!$D$3:$D$7,Capacity!$F$3:$F$7)-Q10,0) -> 2832 | M10: =IF(R10<_xlfn.XLOOKUP(M$1,Capacity!$D$3:$D$7,Capacity!$E$3:$E$7),_xlfn.XLOOKUP(M$1,Capacity!$D$3:$D$7,Capacity!$F$3:$F$7)-R10,0) -> 0 | N10: =IF(S10<_xlfn.XLOOKUP(N$1,Capacity!$D$3:$D$7,Capacity!$E$3:$E$7),_xlfn.XLOOKUP(N$1,Capacity!$D$3:$D$7,Capacity!$F$3:$F$7)-S10,0) -> 1237 | O10: =IF(T10<_xlfn.XLOOKUP(O$1,Capacity!$D$3:$D$7,Capacity!$E$3:$E$7),_xlfn.XLOOKUP(O$1,Capacity!$D$3:$D$7,Capacity!$F$3:$F$7)-T10,0) -> 0 | P10: =IF(U10<_xlfn.XLOOKUP(P$1,Capacity!$D$3:$D$7,Capacity!$E$3:$E$7),_xlfn.XLOOKUP(P$1,Capacity!$D$3:$D$7,Capacity!$F$3:$F$7)-U10,0) -> 0 | Q10: =G10-B10 -> -200 | R10: =H10-C10 -> 2000 | S10: =I10-D10 -> 300 | T10: =J10-E10 -> 2900 | U10: =K10-F10 -> 2300
A11: =A10+1 -> 46032 | B11: =SUMIFS('Demand Projection'!$D$2:$D$169,'Demand Projection'!$B$2:$B$169,B$1,'Demand Projection'!$C$2:$C$169,$A11) -> 0 | C11: =SUMIFS('Demand Projection'!$D$2:$D$169,'Demand Projection'!$B$2:$B$169,C$1,'Demand Projection'!$C$2:$C$169,$A11) -> 0 | D11: =SUMIFS('Demand Projection'!$D$2:$D$169,'Demand Projection'!$B$2:$B$169,D$1,'Demand Projection'!$C$2:$C$169,$A11) -> 0 | E11: =SUMIFS('Demand Projection'!$D$2:$D$169,'Demand Projection'!$B$2:$B$169,E$1,'Demand Projection'!$C$2:$C$169,$A11) -> 0 | F11: =SUMIFS('Demand Projection'!$D$2:$D$169,'Demand Projection'!$B$2:$B$169,F$1,'Demand Projection'!$C$2:$C$169,$A11) -> 0 | G11: {=Q10+IF(ROW()-3<2,0,INDEX(L:L,ROW()-3))} -> 2632 | H11: {=R10+IF(ROW()-3<2,0,INDEX(M:M,ROW()-3))} -> 2000 | I11: {=S10+IF(ROW()-3<2,0,INDEX(N:N,ROW()-3))} -> 300 | J11: {=T10+IF(ROW()-3<2,0,INDEX(O:O,ROW()-3))} -> 2900 | K11: {=U10+IF(ROW()-3<2,0,INDEX(P:P,ROW()-3))} -> 2300 | L11: =IF(Q11<_xlfn.XLOOKUP(L$1,Capacity!$D$3:$D$7,Capacity!$E$3:$E$7),_xlfn.XLOOKUP(L$1,Capacity!$D$3:$D$7,Capacity!$F$3:$F$7)-Q11,0) -> 0 | M11: =IF(R11<_xlfn.XLOOKUP(M$1,Capacity!$D$3:$D$7,Capacity!$E$3:$E$7),_xlfn.XLOOKUP(M$1,Capacity!$D$3:$D$7,Capacity!$F$3:$F$7)-R11,0) -> 0 | N11: =IF(S11<_xlfn.XLOOKUP(N$1,Capacity!$D$3:$D$7,Capacity!$E$3:$E$7),_xlfn.XLOOKUP(N$1,Capacity!$D$3:$D$7,Capacity!$F$3:$F$7)-S11,0) -> 1237 | O11: =IF(T11<_xlfn.XLOOKUP(O$1,Capacity!$D$3:$D$7,Capacity!$E$3:$E$7),_xlfn.XLOOKUP(O$1,Capacity!$D$3:$D$7,Capacity!$F$3:$F$7)-T11,0) -> 0 | P11: =IF(U11<_xlfn.XLOOKUP(P$1,Capacity!$D$3:$D$7,Capacity!$E$3:$E$7),_xlfn.XLOOKUP(P$1,Capacity!$D$3:$D$7,Capacity!$F$3:$F$7)-U11,0) -> 0 | Q11: =G11-B11 -> 2632 | R11: =H11-C11 -> 2000 | S11: =I11-D11 -> 300 | T11: =J11-E11 -> 2900 | U11: =K11-F11 -> 2300
A12: =A11+1 -> 46033 | B12: =SUMIFS('Demand Projection'!$D$2:$D$169,'Demand Projection'!$B$2:$B$169,B$1,'Demand Projection'!$C$2:$C$169,$A12) -> 0 | C12: =SUMIFS('Demand Projection'!$D$2:$D$169,'Demand Projection'!$B$2:$B$169,C$1,'Demand Projection'!$C$2:$C$169,$A12) -> 0 | D12: =SUMIFS('Demand Projection'!$D$2:$D$169,'Demand Projection'!$B$2:$B$169,D$1,'Demand Projection'!$C$2:$C$169,$A12) -> 0 | E12: =SUMIFS('Demand Projection'!$D$2:$D$169,'Demand Projection'!$B$2:$B$169,E$1,'Demand Projection'!$C$2:$C$169,$A12) -> 0 | F12: =SUMIFS('Demand Projection'!$D$2:$D$169,'Demand Projection'!$B$2:$B$169,F$1,'Demand Projection'!$C$2:$C$169,$A12) -> 0 | G12: {=Q11+IF(ROW()-3<2,0,INDEX(L:L,ROW()-3))} -> 5464 | H12: {=R11+IF(ROW()-3<2,0,INDEX(M:M,ROW()-3))} -> 2000 | I12: {=S11+IF(ROW()-3<2,0,INDEX(N:N,ROW()-3))} -> 300 | J12: {=T11+IF(ROW()-3<2,0,INDEX(O:O,ROW()-3))} -> 2900 | K12: {=U11+IF(ROW()-3<2,0,INDEX(P:P,ROW()-3))} -> 2300 | L12: =IF(Q12<_xlfn.XLOOKUP(L$1,Capacity!$D$3:$D$7,Capacity!$E$3:$E$7),_xlfn.XLOOKUP(L$1,Capacity!$D$3:$D$7,Capacity!$F$3:$F$7)-Q12,0) -> 0 | M12: =IF(R12<_xlfn.XLOOKUP(M$1,Capacity!$D$3:$D$7,Capacity!$E$3:$E$7),_xlfn.XLOOKUP(M$1,Capacity!$D$3:$D$7,Capacity!$F$3:$F$7)-R12,0) -> 0 | N12: =IF(S12<_xlfn.XLOOKUP(N$1,Capacity!$D$3:$D$7,Capacity!$E$3:$E$7),_xlfn.XLOOKUP(N$1,Capacity!$D$3:$D$7,Capacity!$F$3:$F$7)-S12,0) -> 1237 | O12: =IF(T12<_xlfn.XLOOKUP(O$1,Capacity!$D$3:$D$7,Capacity!$E$3:$E$7),_xlfn.XLOOKUP(O$1,Capacity!$D$3:$D$7,Capacity!$F$3:$F$7)-T12,0) -> 0 | P12: =IF(U12<_xlfn.XLOOKUP(P$1,Capacity!$D$3:$D$7,Capacity!$E$3:$E$7),_xlfn.XLOOKUP(P$1,Capacity!$D$3:$D$7,Capacity!$F$3:$F$7)-U12,0) -> 0 | Q12: =G12-B12 -> 5464 | R12: =H12-C12 -> 2000 | S12: =I12-D12 -> 300 | T12: =J12-E12 -> 2900 | U12: =K12-F12 -> 2300
A13: =A12+1 -> 46034 | B13: =SUMIFS('Demand Projection'!$D$2:$D$169,'Demand Projection'!$B$2:$B$169,B$1,'Demand Projection'!$C$2:$C$169,$A13) -> 0 | C13: =SUMIFS('Demand Projection'!$D$2:$D$169,'Demand Projection'!$B$2:$B$169,C$1,'Demand Projection'!$C$2:$C$169,$A13) -> 0 | D13: =SUMIFS('Demand Projection'!$D$2:$D$169,'Demand Projection'!$B$2:$B$169,D$1,'Demand Projection'!$C$2:$C$169,$A13) -> 0 | E13: =SUMIFS('Demand Projection'!$D$2:$D$169,'Demand Projection'!$B$2:$B$169,E$1,'Demand Projection'!$C$2:$C$169,$A13) -> 0 | F13: =SUMIFS('Demand Projection'!$D$2:$D$169,'Demand Projection'!$B$2:$B$169,F$1,'Demand Projection'!$C$2:$C$169,$A13) -> 400 | G13: {=Q12+IF(ROW()-3<2,0,INDEX(L:L,ROW()-3))} -> 8296 | H13: {=R12+IF(ROW()-3<2,0,INDEX(M:M,ROW()-3))} -> 2000 | I13: {=S12+IF(ROW()-3<2,0,INDEX(N:N,ROW()-3))} -> 1537 | J13: {=T12+IF(ROW()-3<2,0,INDEX(O:O,ROW()-3))} -> 2900 | K13: {=U12+IF(ROW()-3<2,0,INDEX(P:P,ROW()-3))} -> 2300 | L13: =IF(Q13<_xlfn.XLOOKUP(L$1,Capacity!$D$3:$D$7,Capacity!$E$3:$E$7),_xlfn.XLOOKUP(L$1,Capacity!$D$3:$D$7,Capacity!$F$3:$F$7)-Q13,0) -> 0 | M13: =IF(R13<_xlfn.XLOOKUP(M$1,Capacity!$D$3:$D$7,Capacity!$E$3:$E$7),_xlfn.XLOOKUP(M$1,Capacity!$D$3:$D$7,Capacity!$F$3:$F$7)-R13,0) -> 0 | N13: =IF(S13<_xlfn.XLOOKUP(N$1,Capacity!$D$3:$D$7,Capacity!$E$3:$E$7),_xlfn.XLOOKUP(N$1,Capacity!$D$3:$D$7,Capacity!$F$3:$F$7)-S13,0) -> 0 | O13: =IF(T13<_xlfn.XLOOKUP(O$1,Capacity!$D$3:$D$7,Capacity!$E$3:$E$7),_xlfn.XLOOKUP(O$1,Capacity!$D$3:$D$7,Capacity!$F$3:$F$7)-T13,0) -> 0 | P13: =IF(U13<_xlfn.XLOOKUP(P$1,Capacity!$D$3:$D$7,Capacity!$E$3:$E$7),_xlfn.XLOOKUP(P$1,Capacity!$D$3:$D$7,Capacity!$F$3:$F$7)-U13,0) -> 0 | Q13: =G13-B13 -> 8296 | R13: =H13-C13 -> 2000 | S13: =I13-D13 -> 1537 | T13: =J13-E13 -> 2900 | U13: =K13-F13 -> 1900
A14: =A13+1 -> 46035 | B14: =SUMIFS('Demand Projection'!$D$2:$D$169,'Demand Projection'!$B$2:$B$169,B$1,'Demand Projection'!$C$2:$C$169,$A14) -> 0 | C14: =SUMIFS('Demand Projection'!$D$2:$D$169,'Demand Projection'!$B$2:$B$169,C$1,'Demand Projection'!$C$2:$C$169,$A14) -> 600 | D14: =SUMIFS('Demand Projection'!$D$2:$D$169,'Demand Projection'!$B$2:$B$169,D$1,'Demand Projection'!$C$2:$C$169,$A14) -> 0 | E14: =SUMIFS('Demand Projection'!$D$2:$D$169,'Demand Projection'!$B$2:$B$169,E$1,'Demand Projection'!$C$2:$C$169,$A14) -> 0 | F14: =SUMIFS('Demand Projection'!$D$2:$D$169,'Demand Projection'!$B$2:$B$169,F$1,'Demand Projection'!$C$2:$C$169,$A14) -> 0 | G14: {=Q13+IF(ROW()-3<2,0,INDEX(L:L,ROW()-3))} -> 8296 | H14: {=R13+IF(ROW()-3<2,0,INDEX(M:M,ROW()-3))} -> 2000 | I14: {=S13+IF(ROW()-3<2,0,INDEX(N:N,ROW()-3))} -> 2774 | J14: {=T13+IF(ROW()-3<2,0,INDEX(O:O,ROW()-3))} -> 2900 | K14: {=U13+IF(ROW()-3<2,0,INDEX(P:P,ROW()-3))} -> 1900 | L14: =IF(Q14<_xlfn.XLOOKUP(L$1,Capacity!$D$3:$D$7,Capacity!$E$3:$E$7),_xlfn.XLOOKUP(L$1,Capacity!$D$3:$D$7,Capacity!$F$3:$F$7)-Q14,0) -> 0 | M14: =IF(R14<_xlfn.XLOOKUP(M$1,Capacity!$D$3:$D$7,Capacity!$E$3:$E$7),_xlfn.XLOOKUP(M$1,Capacity!$D$3:$D$7,Capacity!$F$3:$F$7)-R14,0) -> 0 | N14: =IF(S14<_xlfn.XLOOKUP(N$1,Capacity!$D$3:$D$7,Capacity!$E$3:$E$7),_xlfn.XLOOKUP(N$1,Capacity!$D$3:$D$7,Capacity!$F$3:$F$7)-S14,0) -> 0 | O14: =IF(T14<_xlfn.XLOOKUP(O$1,Capacity!$D$3:$D$7,Capacity!$E$3:$E$7),_xlfn.XLOOKUP(O$1,Capacity!$D$3:$D$7,Capacity!$F$3:$F$7)-T14,0) -> 0 | P14: =IF(U14<_xlfn.XLOOKUP(P$1,Capacity!$D$3:$D$7,Capacity!$E$3:$E$7),_xlfn.XLOOKUP(P$1,Capacity!$D$3:$D$7,Capacity!$F$3:$F$7)-U14,0) -> 0 | Q14: =G14-B14 -> 8296 | R14: =H14-C14 -> 1400 | S14: =I14-D14 -> 2774 | T14: =J14-E14 -> 2900 | U14: =K14-F14 -> 1900
... A366: =A365+1 -> 46387 | B366: =SUMIFS('Demand Projection'!$D$2:$D$169,'Demand Projection'!$B$2:$B$169,B$1,'Demand Projection'!$C$2:$C$169,$A366) -> 0 | C366: =SUMIFS('Demand Projection'!$D$2:$D$169,'Demand Projection'!$B$2:$B$169,C$1,'Demand Projection'!$C$2:$C$169,$A366) -> 0 | D366: =SUMIFS('Demand Projection'!$D$2:$D$169,'Demand Projection'!$B$2:$B$169,D$1,'Demand Projection'!$C$2:$C$169,$A366) -> 0 | E366: =SUMIFS('Demand Projection'!$D$2:$D$169,'Demand Projection'!$B$2:$B$169,E$1,'Demand Projection'!$C$2:$C$169,$A366) -> 0 | F366: =SUMIFS('Demand Projection'!$D$2:$D$169,'Demand Projection'!$B$2:$B$169,F$1,'Demand Projection'!$C$2:$C$169,$A366) -> 0 | G366: {=Q365+IF(ROW()-3<2,0,INDEX(L:L,ROW()-3))} -> 2219 | H366: {=R365+IF(ROW()-3<2,0,INDEX(M:M,ROW()-3))} -> 1309 | I366: {=S365+IF(ROW()-3<2,0,INDEX(N:N,ROW()-3))} -> 4171 | J366: {=T365+IF(ROW()-3<2,0,INDEX(O:O,ROW()-3))} -> 3500 | K366: {=U365+IF(ROW()-3<2,0,INDEX(P:P,ROW()-3))} -> 2183 | L366: =IF(Q366<_xlfn.XLOOKUP(L$1,Capacity!$D$3:$D$7,Capacity!$E$3:$E$7),_xlfn.XLOOKUP(L$1,Capacity!$D$3:$D$7,Capacity!$F$3:$F$7)-Q366,0) -> 0 | M366: =IF(R366<_xlfn.XLOOKUP(M$1,Capacity!$D$3:$D$7,Capacity!$E$3:$E$7),_xlfn.XLOOKUP(M$1,Capacity!$D$3:$D$7,Capacity!$F$3:$F$7)-R366,0) -> 0 | N366: =IF(S366<_xlfn.XLOOKUP(N$1,Capacity!$D$3:$D$7,Capacity!$E$3:$E$7),_xlfn.XLOOKUP(N$1,Capacity!$D$3:$D$7,Capacity!$F$3:$F$7)-S366,0) -> 0 | O366: =IF(T366<_xlfn.XLOOKUP(O$1,Capacity!$D$3:$D$7,Capacity!$E$3:$E$7),_xlfn.XLOOKUP(O$1,Capacity!$D$3:$D$7,Capacity!$F$3:$F$7)-T366,0) -> 0 | P366: =IF(U366<_xlfn.XLOOKUP(P$1,Capacity!$D$3:$D$7,Capacity!$E$3:$E$7),_xlfn.XLOOKUP(P$1,Capacity!$D$3:$D$7,Capacity!$F$3:$F$7)-U366,0) -> 0 | Q366: =G366-B366 -> 2219 | R366: =H366-C366 -> 1309 | S366: =I366-D366 -> 4171 | T366: =J366-E366 -> 3500 | U366: =K366-F366 -> 2183

Sheet Reorder Events
A1: Date | B1: SKU | C1: Reorder Qty
A2: {=_xlfn.LET( _xlpm.d,'Reorder Calc'!$A$2:$A$366, _xlpm.a,'Reorder Calc'!$L$2:$L$366, _xlpm.b,'Reorder Calc'!$M$2:$M$366, _xlpm.c,'Reorder Calc'!$N$2:$N$366, _xlpm.e,'Reorder Calc'!$O$2:$O$366, _xlpm.f,'Reorder Calc'!$P$2:$P$366, _xlpm.x, _xlfn.VSTACK( _xlfn._xlws.FILTER(_xlfn.HSTACK(_xlpm.d,IF(_xlpm.a>0,"SKU PROD A",""),_xlpm.a),_xlpm.a>0), _xlfn._xlws.FILTER(_xlfn.HSTACK(_xlpm.d,IF(_xlpm.b>0,"SKU PROD B",""),_xlpm.b),_xlpm.b>0), _xlfn._xlws.FILTER(_xlfn.HSTACK(_xlpm.d,IF(_xlpm.c>0,"SKU PROD C",""),_xlpm.c>0), _xlpm.c>0), _xlfn._xlws.FILTER(_xlfn.HSTACK(_xlpm.d,IF(_xlpm.e>0,"SKU PROD D",""),_xlpm.e),_xlpm.e>0), _xlfn._xlws.FILTER(_xlfn.HSTACK(_xlpm.d,IF(_xlpm.f>0,"SKU PROD E",""),_xlpm.f),_xlpm.f>0) ), _xlfn.SORTBY(_xlpm.x,_xlfn.CHOOSECOLS(_xlpm.x,1),1,_xlfn.CHOOSECOLS(_xlpm.x,2),1) )} -> 46029 | B2: SKU PROD A | C2: 2832
A3: 46030 | B3: SKU PROD A | C3: 2832
A4: 46031 | B4: SKU PROD A | C4: 2832
A5: 46031 | B5: SKU PROD C | C5: TRUE
A6: 46032 | B6: SKU PROD C | C6: TRUE
A7: 46033 | B7: SKU PROD C | C7: TRUE
A8: 46050 | B8: SKU PROD D | C8: 4274
A9: 46050 | B9: SKU PROD E | C9: 2283
A10: 46051 | B10: SKU PROD D | C10: 4274
A11: 46051 | B11: SKU PROD E | C11: 2283
A12: 46052 | B12: SKU PROD D | C12: 4274
A13: 46052 | B13: SKU PROD E | C13: 2283
A14: 46056 | B14: SKU PROD B | C14: 11470
A15: 46057 | B15: SKU PROD B | C15: 11470
A16: 46058 | B16: SKU PROD B | C16: 11470
A17: 46086 | B17: SKU PROD C | C17: TRUE
A18: 46087 | B18: SKU PROD C | C18: TRUE
A19: 46088 | B19: SKU PROD C | C19: TRUE
A20: 46105 | B20: SKU PROD A | C20: 2493
A21: 46106 | B21: SKU PROD A | C21: 2493
A22: 46107 | B22: SKU PROD A | C22: 2493
A23: 46140 | B23: SKU PROD D | C23: 5763
A24: 46140 | B24: SKU PROD E | C24: 3096
A25: 46141 | B25: SKU PROD D | C25: 5763
A26: 46141 | B26: SKU PROD E | C26: 3096
A27: 46142 | B27: SKU PROD D | C27: 5763
A28: 46142 | B28: SKU PROD E | C28: 3096
A29: 46147 | B29: SKU PROD C | C29: TRUE
A30: 46148 | B30: SKU PROD C | C30: TRUE
A31: 46149 | B31: SKU PROD C | C31: TRUE
A32: 46166 | B32: SKU PROD A | C32: 2083
A33: 46167 | B33: SKU PROD A | C33: 2083
A34: 46168 | B34: SKU PROD A | C34: 2083
A35: 46206 | B35: SKU PROD B | C35: 10917
A36: 46207 | B36: SKU PROD B | C36: 10917
A37: 46208 | B37: SKU PROD B | C37: 10917
A38: 46208 | B38: SKU PROD C | C38: TRUE
A39: 46209 | B39: SKU PROD C | C39: TRUE
A40: 46210 | B40: SKU PROD C | C40: TRUE
...
